functions:
	void testError()
		error("This is a test error message")

function start()
	integer:
		result = 0
	
	// Test explicit error throwing with function call
	testError() onError:
		print("Caught error:")
		print(error)
		result = -1
	
	print("Final result:")
	print(result) 